Workbook
Name Slicer_Average_Unit_Price: #N/A
Name Slicer_Cost_Of_Sales: #N/A
Name Slicer_Gross_Profit: #N/A
Name Slicer_Quantity_Sold: #N/A
Name Slicer_Sales: #N/A
Name Slicer_Total_Cost_Of_Sales: #N/A
Name Slicer_Total_Quantity_Sold: #N/A
Name Slicer_Total_Sales: #N/A
Name Slicer_Years__Date: #N/A
Name Slicer_Years__Month: #N/A

Sheet Dashboard1
B1: FNB SALES PERFORMANCE DASHBOARD
B3: Executive overview • Sales • Pricing • Profitability • Demand
B4: TOTAL SALES | E4: TOTAL QUANTITY | H4: GROSS PROFIT | K4: GROSS PROFIT % | N4: AVG UNIT PRICE
B5: =GETPIVOTDATA("Sales",pivot!$A$3) -> 1.8690983e+08 | E5: =GETPIVOTDATA("Quantity Sold",pivot!$A$7) -> 5279872 | H5: =GETPIVOTDATA("Gross Profit",'Pivot Daily Analysis'!$A$3) -> -7116281.2 | K5: =(SUM('Sales Master'!B2:B1054)-SUM('Sales Master'!C2:C1054))/SUM('Sales Master'!B2:B1054) -> -0.038073339 | N5: ='Sales Master'!D1058 -> 35.400447
B53: Key finding:** despite substantial revenue and volume, the product recorded an overall gross loss. **High sales volume does not automatically mean high profitability
B54: ## 💡 Key Insights
B56: 1. Volume without value.** ~R186.91M in sales and 5.28M units sold still produced a net gross loss of R7.12M — revenue and unit counts were rising while profitability was not,
B57: 2. Customers are price-sensitive.** Periods of lower selling price consistently lined up with stronger demand, a signature of elastic demand — discounting moves units fast, but every point of price cut compounds against margin.
B58: 3. Promotions moved volume, not necessarily value.** Promotional periods look successful on a units-sold view and materially weaker on a profit-per-unit view — the two tell different stories from the same data.
B59: 4. Price and profit need to be watched together.** No single metric (sales, units, or price alone) explained the loss — it only became visible once price, cost, and quantity were modelled together as elasticity.
B62: ## 🎯 Business Recommendations
B64: | 1 | Review pricing strategy** — ensure selling price consistently covers cost of sales | Removes the structural cause of the gross loss |
B65: | 2 | Optimise promotional pricing** — test discount depths that stimulate demand without dropping below margin-safe thresholds | Keeps the demand lift from promotions without the profit leak |
B66: | 3 | Monitor unit economics** — track gross profit per unit alongside sales volume, not sales volume alone | Catches value-destroying growth before it compounds |
B67: | 4 | Prioritise profitable growth** — stop treating revenue and unit growth as success metrics in isolation | Reframes decision-making around margin, not vanity metrics |
B68: | 5 | Build a live pricing performance dashboard** — price, quantity, margin and elasticity in one view | Turns this from a one-off finding into an ongoing early-warning system |

Sheet Pivot Monthly analysis
A2: Monthly sales Trend
A3: Row Labels | B3: Sum of Total Sales
A4: Jan | B4: 13107463
A5: Feb | B5: 15573874
A6: Mar | B6: 16500726
A7: Apr | B7: 19056617
A8: May | B8: 21249505
A9: Jun | B9: 18560187
A10: Jul | B10: 11936229
A11: Aug | B11: 18288376
A12: Sept | B12: 15572895
A13: Oct | B13: 13082831
A14: Nov | B14: 11020532
A15: Dec | B15: 12960592
A16: Grand Total | B16: 1.8690983e+08
A19: Monthly quantity Trend
A20: Row Labels | B20: Sum of Total Quantity Sold
A21: Jan | B21: 362266
A22: Feb | B22: 438778
A23: Mar | B23: 463694
A24: Apr | B24: 534028
A25: May | B25: 602866
A26: Jun | B26: 532907
A27: Jul | B27: 333702
A28: Aug | B28: 543092
A29: Sept | B29: 461251
A30: Oct | B30: 363704
A31: Nov | B31: 297544
A32: Dec | B32: 346040
A33: Grand Total | B33: 5279872
A37: Monthly Gross Profit
A38: Row Labels | B38: Sum of Gross Profit
A39: Jan | B39: -396860.52
A40: Feb | B40: -380664.1
A41: Mar | B41: -432359.9
A42: Apr | B42: -837431.78
A43: May | B43: -1079831.7
A44: Jun | B44: -774931.75
A45: Jul | B45: -166252.11
A46: Aug | B46: -926771.3
...

Sheet pivot
A2: Total Sales
A3: Sum of Sales
A4: 1.8690983e+08
A6: Total Quantity
A7: Sum of Quantity Sold
A8: 5279872

Sheet sales master pivot
A3: Sum of Sales | B3: Count of Cost Of Sales
A4: 7.4763931e+08 | B4: 1058

Sheet Sales Master
A1: Date | B1: Sales | C1: Cost Of Sales | D1: Quantity Sold | E1: Gross Profit
A2: 41638 | B2: 223937.97 | C2: 230079.62 | D2: 6827 | E2: =SalesMasterTable[[#This Row],[Sales]]-SalesMasterTable[[#This Row],[Cost Of Sales]] -> -6141.6531
A3: 41639 | B3: 300345.48 | C3: 306986.12 | D3: 9268 | E3: =SalesMasterTable[[#This Row],[Sales]]-SalesMasterTable[[#This Row],[Cost Of Sales]] -> -6640.6359
A4: 41640 | B4: 86782.468 | C4: 87986.318 | D4: 2678 | E4: =SalesMasterTable[[#This Row],[Sales]]-SalesMasterTable[[#This Row],[Cost Of Sales]] -> -1203.8505
A5: 41641 | B5: 200173.12 | C5: 202881.18 | D5: 6175 | E5: =SalesMasterTable[[#This Row],[Sales]]-SalesMasterTable[[#This Row],[Cost Of Sales]] -> -2708.061
A6: 41642 | B6: 326906.07 | C6: 333806.29 | D6: 10084 | E6: =SalesMasterTable[[#This Row],[Sales]]-SalesMasterTable[[#This Row],[Cost Of Sales]] -> -6900.2177
A7: 41643 | B7: 307043.94 | C7: 313652.35 | D7: 9470 | E7: =SalesMasterTable[[#This Row],[Sales]]-SalesMasterTable[[#This Row],[Cost Of Sales]] -> -6608.4129
A8: 41644 | B8: 179188.88 | C8: 183083.28 | D8: 5524 | E8: =SalesMasterTable[[#This Row],[Sales]]-SalesMasterTable[[#This Row],[Cost Of Sales]] -> -3894.4005
A9: 41645 | B9: 306351.95 | C9: 313446.07 | D9: 9448 | E9: =SalesMasterTable[[#This Row],[Sales]]-SalesMasterTable[[#This Row],[Cost Of Sales]] -> -7094.1173
A10: 41646 | B10: 224020.41 | C10: 229533.97 | D10: 6911 | E10: =SalesMasterTable[[#This Row],[Sales]]-SalesMasterTable[[#This Row],[Cost Of Sales]] -> -5513.5638
A11: 41647 | B11: 101836.4 | C11: 99381.968 | D11: 2990 | E11: =SalesMasterTable[[#This Row],[Sales]]-SalesMasterTable[[#This Row],[Cost Of Sales]] -> 2454.4347
A12: 41648 | B12: 107804.3 | C12: 104816.46 | D12: 3159 | E12: =SalesMasterTable[[#This Row],[Sales]]-SalesMasterTable[[#This Row],[Cost Of Sales]] -> 2987.8464
A13: 41649 | B13: 144829.96 | C13: 141334 | D13: 4246 | E13: =SalesMasterTable[[#This Row],[Sales]]-SalesMasterTable[[#This Row],[Cost Of Sales]] -> 3495.9604
... A1054: 42690 | B1054: 77229.972 | C1054: 71428.87 | D1054: 1763 | E1054: =SalesMasterTable[[#This Row],[Sales]]-SalesMasterTable[[#This Row],[Cost Of Sales]] -> 5801.1019
B1055: =SUBTOTAL(109,SalesMasterTable[Sales]) -> 1.8690983e+08 | C1055: =SUBTOTAL(109,SalesMasterTable[Cost Of Sales]) -> 1.9402611e+08 | D1055: =SUBTOTAL(109,SalesMasterTable[Quantity Sold]) -> 5279872 | E1055: =SUBTOTAL(109,SalesMasterTable[Gross Profit]) -> -7116281.2
B1057: Sales | C1057: Quantity Sold | D1057: Average Unit Price
A1058: Average Unit Price | B1058: =B1061 -> 1.8690983e+08 | C1058: =SalesMasterTable[[#Totals],[Quantity Sold]] -> 5279872 | D1058: =B1058/C1058 -> 35.400447
B1060: Sales | C1060: Gross Profit | D1060: Gross Profit %
A1061: Gross Profit % | B1061: =SalesMasterTable[[#Totals],[Sales]] -> 1.8690983e+08 | C1061: =SalesMasterTable[[#Totals],[Sales]]-SalesMasterTable[[#Totals],[Cost Of Sales]] -> -7116281.2 | D1061: =SalesMasterTable[[#Totals],[Gross Profit]]/SalesMasterTable[[#Totals],[Sales]]*100 -> -3.8073339

Sheet Sheet1
A1: Date | B1: Sales | C1: Cost Of Sales | D1: Gross Profit | E1: Gross Profit % | F1: Quantity Sold
A2: 41638 | B2: 223937.97 | C2: 230079.62 | D2: =SalesMasterTable[[#This Row],[Sales]]-SalesMasterTable[[#This Row],[Cost Of Sales]] -> -6141.6531 | E2: -0.027425689 | F2: 6827
A3: 41639 | B3: 300345.48 | C3: 306986.12 | D3: =SalesMasterTable[[#This Row],[Sales]]-SalesMasterTable[[#This Row],[Cost Of Sales]] -> -6640.6359 | E3: -0.022109991 | F3: 9268
A4: 41640 | B4: 86782.468 | C4: 87986.318 | D4: =SalesMasterTable[[#This Row],[Sales]]-SalesMasterTable[[#This Row],[Cost Of Sales]] -> -1203.8505 | E4: -0.013872047 | F4: 2678
A5: 41641 | B5: 200173.12 | C5: 202881.18 | D5: =SalesMasterTable[[#This Row],[Sales]]-SalesMasterTable[[#This Row],[Cost Of Sales]] -> -2708.061 | E5: -0.013528595 | F5: 6175
A6: 41642 | B6: 326906.07 | C6: 333806.29 | D6: =SalesMasterTable[[#This Row],[Sales]]-SalesMasterTable[[#This Row],[Cost Of Sales]] -> -6900.2177 | E6: -0.021107646 | F6: 10084
A7: 41643 | B7: 307043.94 | C7: 313652.35 | D7: =SalesMasterTable[[#This Row],[Sales]]-SalesMasterTable[[#This Row],[Cost Of Sales]] -> -6608.4129 | E7: -0.021522695 | F7: 9470
A8: 41644 | B8: 179188.88 | C8: 183083.28 | D8: =SalesMasterTable[[#This Row],[Sales]]-SalesMasterTable[[#This Row],[Cost Of Sales]] -> -3894.4005 | E8: -0.021733494 | F8: 5524
A9: 41645 | B9: 306351.95 | C9: 313446.07 | D9: =SalesMasterTable[[#This Row],[Sales]]-SalesMasterTable[[#This Row],[Cost Of Sales]] -> -7094.1173 | E9: -0.023156756 | F9: 9448
A10: 41646 | B10: 224020.41 | C10: 229533.97 | D10: =SalesMasterTable[[#This Row],[Sales]]-SalesMasterTable[[#This Row],[Cost Of Sales]] -> -5513.5638 | E10: -0.024611881 | F10: 6911

Sheet Pivot Daily Analysis
A2: Gross Profit
A3: Sum of Gross Profit
A4: -7116281.2
A6: Gross Profit %
A7: Average of Gross Profit %
A8: -0.0087497665

Sheet Daily Sales Analysis pivot
A1: Quarters (Date) | B1: (All)
A3: Row Labels | B3: Sum of Cost Of Sales | C3: Sum of Sales
A4: 2013 | B4: 537065.74 | C4: 524283.45
A5: 2014 | B5: 77680850 | C5: 75414976
A6: 2015 | B6: 67917204 | C6: 64017593
A7: 2016 | B7: 47890990 | C7: 46952976
A8: Grand Total | B8: 1.9402611e+08 | C8: 1.8690983e+08
A17: Row Labels | B17: Sum of Cost Of Sales | C17: Sum of Sales
A18: 2013 | B18: 537065.74 | C18: 524283.45
A19: 2014 | B19: 77680850 | C19: 75414976
A20: 2015 | B20: 67917204 | C20: 64017593
A21: 2016 | B21: 47890990 | C21: 46952976
A22: Grand Total | B22: 1.9402611e+08 | C22: 1.8690983e+08

Sheet Daily Analysis
A1: Date | B1: Sales | C1: Cost Of Sales | D1: Quantity Sold | E1: Daily Sales Price Per Unit | F1: Gross Profit | G1: Gross Profit % | H1: Gross Profit Per Unit
A2: 41638 | B2: 223937.97 | C2: 230079.62 | D2: 6827 | E2: =B2/D2 -> 32.801812 | F2: =B2-C2 -> -6141.6531 | G2: =F2/B2 -> -0.027425689 | H2: =F2/D2 -> -0.8996123
A3: 41639 | B3: 300345.48 | C3: 306986.12 | D3: 9268 | E3: =B3/D3 -> 32.40672 | F3: =B3-C3 -> -6640.6359 | G3: =F3/B3 -> -0.022109991 | H3: =F3/D3 -> -0.71651229
A4: 41640 | B4: 86782.468 | C4: 87986.318 | D4: 2678 | E4: =B4/D4 -> 32.405701 | F4: =B4-C4 -> -1203.8505 | G4: =F4/B4 -> -0.013872047 | H4: =F4/D4 -> -0.44953342
A5: 41641 | B5: 200173.12 | C5: 202881.18 | D5: 6175 | E5: =B5/D5 -> 32.416699 | F5: =B5-C5 -> -2708.061 | G5: =F5/B5 -> -0.013528595 | H5: =F5/D5 -> -0.43855238
A6: 41642 | B6: 326906.07 | C6: 333806.29 | D6: 10084 | E6: =B6/D6 -> 32.418294 | F6: =B6-C6 -> -6900.2177 | G6: =F6/B6 -> -0.021107646 | H6: =F6/D6 -> -0.68427387
A7: 41643 | B7: 307043.94 | C7: 313652.35 | D7: 9470 | E7: =B7/D7 -> 32.422802 | F7: =B7-C7 -> -6608.4129 | G7: =F7/B7 -> -0.021522695 | H7: =F7/D7 -> -0.69782607
A8: 41644 | B8: 179188.88 | C8: 183083.28 | D8: 5524 | E8: =B8/D8 -> 32.438248 | F8: =B8-C8 -> -3894.4005 | G8: =F8/B8 -> -0.021733494 | H8: =F8/D8 -> -0.70499647
A9: 41645 | B9: 306351.95 | C9: 313446.07 | D9: 9448 | E9: =B9/D9 -> 32.425058 | F9: =B9-C9 -> -7094.1173 | G9: =F9/B9 -> -0.023156756 | H9: =F9/D9 -> -0.75085915
A10: 41646 | B10: 224020.41 | C10: 229533.97 | D10: 6911 | E10: =B10/D10 -> 32.41505 | F10: =B10-C10 -> -5513.5638 | G10: =F10/B10 -> -0.024611881 | H10: =F10/D10 -> -0.79779536
A11: 41647 | B11: 101836.4 | C11: 99381.968 | D11: 2990 | E11: =B11/D11 -> 34.058997 | F11: =B11-C11 -> 2454.4347 | G11: =F11/B11 -> 0.024101742 | H11: =F11/D11 -> 0.82088118
A12: 41648 | B12: 107804.3 | C12: 104816.46 | D12: 3159 | E12: =B12/D12 -> 34.126086 | F12: =B12-C12 -> 2987.8464 | G12: =F12/B12 -> 0.027715465 | H12: =F12/D12 -> 0.94582033
A13: 41649 | B13: 144829.96 | C13: 141334 | D13: 4246 | E13: =B13/D13 -> 34.10974 | F13: =B13-C13 -> 3495.9604 | G13: =F13/B13 -> 0.024138379 | H13: =F13/D13 -> 0.82335385
... A1054: 42690 | B1054: 77229.972 | C1054: 71428.87 | D1054: 1763 | E1054: =B1054/D1054 -> 43.805997 | F1054: =B1054-C1054 -> 5801.1019 | G1054: =F1054/B1054 -> 0.075114645 | H1054: =F1054/D1054 -> 3.2904719
G1055: =SUM(G2:G1054) -> -9.2135042
B1056: =SUM(B2:B1055) -> 1.8690983e+08 | F1056: =SUM(F2:F1055) -> -7116281.2 | G1056: =F1056/B1056 -> -0.038073339
F1061: =F1056/B1056 -> -0.038073339

Sheet Monthly Analysis
A1: Month | B1: Total Sales | C1: Total Cost Of Sales | D1: Total Quantity Sold | E1: Average Unit Price | F1: Gross Profit | G1: Gross Profit %
A2: 41609 | B2: 524283.45 | C2: 537065.74 | D2: 16095 | E2: =B2/D2 -> 32.574306 | F2: =B2-C2 -> -12782.289 | G2: =F2/B2 -> -0.024380493
A3: 41640 | B3: 4008180.5 | C3: 3995719.8 | D3: 119965 | E3: =B3/D3 -> 33.411249 | F3: =B3-C3 -> 12460.645 | G3: =F3/B3 -> 0.0031088035
A4: 41671 | B4: 5780487.2 | C4: 5913478.6 | D4: 178035 | E4: =B4/D4 -> 32.468263 | F4: =B4-C4 -> -132991.39 | G4: =F4/B4 -> -0.023006951
A5: 41699 | B5: 8279517.2 | C5: 8415654 | D5: 252836 | E5: =B5/D5 -> 32.746591 | F5: =B5-C5 -> -136136.84 | G5: =F5/B5 -> -0.016442607
A6: 41730 | B6: 6435743.3 | C6: 6479643.6 | D6: 190091 | E6: =B6/D6 -> 33.856118 | F6: =B6-C6 -> -43900.351 | G6: =F6/B6 -> -0.0068213335
A7: 41760 | B7: 7694906.2 | C7: 8017240.4 | D7: 235793 | E7: =B7/D7 -> 32.634159 | F7: =B7-C7 -> -322334.26 | G7: =F7/B7 -> -0.041889304
A8: 41791 | B8: 6456943.6 | C8: 6645843.7 | D8: 198857 | E8: =B8/D8 -> 32.470286 | F8: =B8-C8 -> -188900.01 | G8: =F8/B8 -> -0.029255329
A9: 41821 | B9: 4933710.8 | C9: 5004894.9 | D9: 147449 | E9: =B9/D9 -> 33.460456 | F9: =B9-C9 -> -71184.101 | G9: =F9/B9 -> -0.014428106
A10: 41852 | B10: 10010378 | C10: 10524432 | D10: 310572 | E10: =B10/D10 -> 32.232069 | F10: =B10-C10 -> -514054.14 | G10: =F10/B10 -> -0.051352119
A11: 41883 | B11: 7643452.7 | C11: 8193560 | D11: 237742 | E11: =B11/D11 -> 32.150199 | F11: =B11-C11 -> -550107.35 | G11: =F11/B11 -> -0.071971055
A12: 41913 | B12: 5924683.4 | C12: 6038461.3 | D12: 171709 | E12: =B12/D12 -> 34.50421 | F12: =B12-C12 -> -113777.94 | G12: =F12/B12 -> -0.019204053
A13: 41944 | B13: 2631353.3 | C13: 2517124.8 | D13: 68569 | E13: =B13/D13 -> 38.375262 | F13: =B13-C13 -> 114228.51 | G13: =F13/B13 -> 0.043410554
... A37: 42675 | B37: 1851029.9 | C37: 1724472.9 | D37: 43107 | E37: =B37/D37 -> 42.940355 | F37: =B37-C37 -> 126556.98 | G37: =F37/B37 -> 0.06837112
E39: =SUM(E2:E38) -> 1299.4915
E40: =E39/37 -> 35.121391

Sheet Sheet4
A3: Row Labels | B3: Sum of Quantity Sold
A4: 43.805997 | B4: 1763
A5: 43.791442 | B5: 2181
A6: 42.95604 | B6: 877
A7: 42.950915 | B7: 1901
A8: 42.940282 | B8: 2281
A9: 42.939862 | B9: 3748
A10: 42.936428 | B10: 2621
A11: 42.934906 | B11: 3843
A12: 42.934671 | B12: 1666
A13: 42.931638 | B13: 1332
A14: 42.929743 | B14: 2046
A15: 42.928021 | B15: 880
... A20: 42.917756 | B20: 1618
A21: 42.86797 | B21: 521 | D21: Average of Quantity Sold
A22: 42.836998 | B22: 709 | D22: 5014.1235
A23: 42.823923 | B23: 2266
A24: 42.800301 | B24: 4720
A25: 42.76444 | B25: 1280 | D25: Sum of Daily Sales Price Per Unit
A26: 42.750887 | B26: 2537 | D26: 39037.713
A27: 42.74994 | B27: 3938
A28: 42.743768 | B28: 2472
A29: 42.731124 | B29: 2971
A30: 42.721535 | B30: 1639
A31: 42.717341 | B31: 1096
A32: 42.713768 | B32: 2284
A33: 42.708716 | B33: 2068
A34: 42.701049 | B34: 1257
A35: 42.694773 | B35: 2249
A36: 42.693163 | B36: 940
A37: 42.680808 | B37: 1582
A38: 42.672638 | B38: 2929
... A1055: 30.70237 | B1055: 15291
A1056: Grand Total | B1056: 5279872

Sheet Price vs Quantity
A1: Daily Sales Price Per Unit | B1: Quantity Sold
A2: ='Daily Analysis'!E2 -> 32.801812 | B2: ='Daily Analysis'!D2 -> 6827
A3: ='Daily Analysis'!E3 -> 32.40672 | B3: ='Daily Analysis'!D3 -> 9268
A4: ='Daily Analysis'!E4 -> 32.405701 | B4: ='Daily Analysis'!D4 -> 2678
A5: ='Daily Analysis'!E5 -> 32.416699 | B5: ='Daily Analysis'!D5 -> 6175
A6: ='Daily Analysis'!E6 -> 32.418294 | B6: ='Daily Analysis'!D6 -> 10084
A7: ='Daily Analysis'!E7 -> 32.422802 | B7: ='Daily Analysis'!D7 -> 9470
A8: ='Daily Analysis'!E8 -> 32.438248 | B8: ='Daily Analysis'!D8 -> 5524
A9: ='Daily Analysis'!E9 -> 32.425058 | B9: ='Daily Analysis'!D9 -> 9448
A10: ='Daily Analysis'!E10 -> 32.41505 | B10: ='Daily Analysis'!D10 -> 6911
A11: ='Daily Analysis'!E11 -> 34.058997 | B11: ='Daily Analysis'!D11 -> 2990
A12: ='Daily Analysis'!E12 -> 34.126086 | B12: ='Daily Analysis'!D12 -> 3159
A13: ='Daily Analysis'!E13 -> 34.10974 | B13: ='Daily Analysis'!D13 -> 4246
... A1054: ='Daily Analysis'!E1054 -> 43.805997 | B1054: ='Daily Analysis'!D1054 -> 1763
